<?xml version="1.0" ?>
<!-- =================================================================================== -->
<!-- |    This document was autogenerated by xacro from drone.urdf.xacro               | -->
<!-- |    EDITING THIS FILE BY HAND IS NOT RECOMMENDED                                 | -->
<!-- =================================================================================== -->
<robot name="drone">
  <material name="blue">
    <color rgba="0 0 1 1"/>
  </material>
  <material name="grey">
    <color rgba="0.75 0.75 0.75 1"/>
  </material>
  <material name="WHITE_MTL">
    <color rgba="0 255 255 1.0"/>
    <!-- rviz green color -->
  </material>
  <link name="dummy_link">
    <pose>0 0 0 0 0 0</pose>
  </link>
  <joint name="dummy_joint" type="fixed">
    <parent link="dummy_link"/>
    <child link="base_link"/>
  </joint>
  <link name="base_link">
    <inertial>
      <origin rpy="0 0 0" xyz="0 0 0.02"/>
      <mass value="2"/>
      <inertia ixx="0.0049386751078625" ixy="0" ixz="0" iyy="0.0049386751078625" iyz="0" izz="0.009296329614800002"/>
    </inertial>
    <visual>
      <origin rpy="0 0 0" xyz="0 0 0"/>
      <geometry>
        <mesh filename="package://drone/meshes/base_link.STL"/>
      </geometry>
      <material name="WHITE_MTL"/>
    </visual>
    <collision>
      <origin rpy="0 0 0" xyz="0 0 0"/>
      <geometry>
        <mesh filename="package://drone/meshes/base_link.STL"/>
      </geometry>
    </collision>
  </link>
  <gazebo reference="base_link">
    <material>Gazebo/Black</material>
  </gazebo>
  <link name="prop_1">
    <inertial>
      <origin rpy="0 0 0" xyz="1.38777878078145E-17 1.6252017232217E-05 1.38777878078145E-17"/>
      <mass value="0.00097325565732889"/>
      <inertia ixx="6.26992620308679E-07" ixy="-3.30120444584961E-24" ixz="7.98941079078638E-09" iyy="6.38900379274268E-07" iyz="1.24797735656839E-23" izz="1.55888758686964E-08"/>
    </inertial>
    <visual>
      <origin rpy="0 0 0" xyz="0 0 0"/>
      <geometry>
        <mesh filename="package://drone/meshes/prop_1.STL"/>
      </geometry>
      <material name="">
        <color rgba="0.286274509803922 0.662745098039216 0.329411764705882 1"/>
      </material>
    </visual>
    <collision>
      <origin rpy="0 0 0" xyz="0 0 0"/>
      <geometry>
        <mesh filename="package://drone/meshes/prop_1.STL"/>
      </geometry>
    </collision>
  </link>
  <joint name="motor_1" type="continuous">
    <origin rpy="1.5708 0 1.59" xyz="-0.084853 0.084853 0.0335"/>
    <parent link="base_link"/>
    <child link="prop_1"/>
    <axis xyz="0 1 0"/>
    <limit effort="1000000" lower="-1000000" upper="1000000" velocity="1000000"/>
  </joint>
  <link name="prop_2">
    <inertial>
      <origin rpy="0 0 0" xyz="0 1.6252017232217E-05 -2.77555756156289E-17"/>
      <mass value="0.000973255657328893"/>
      <inertia ixx="6.26992620308679E-07" ixy="2.22863875678516E-24" ixz="7.98941079078498E-09" iyy="6.38900379274269E-07" iyz="-7.82816974953869E-25" izz="1.55888758686964E-08"/>
    </inertial>
    <visual>
      <origin rpy="0 0 0" xyz="0 0 0"/>
      <geometry>
        <mesh filename="package://drone/meshes/prop_2.STL"/>
      </geometry>
      <material name="">
        <color rgba="0.286274509803922 0.662745098039216 0.329411764705882 1"/>
      </material>
    </visual>
    <collision>
      <origin rpy="0 0 0" xyz="0 0 0"/>
      <geometry>
        <mesh filename="package://drone/meshes/prop_2.STL"/>
      </geometry>
    </collision>
  </link>
  <joint name="motor_2" type="continuous">
    <origin rpy="1.5708 0 -3.102" xyz="0.084853 0.084853 0.0335"/>
    <parent link="base_link"/>
    <child link="prop_2"/>
    <axis xyz="0 1 0"/>
    <limit effort="1000000" lower="-1000000" upper="1000000" velocity="1000000"/>
  </joint>
  <link name="prop_3">
    <inertial>
      <origin rpy="0 0 0" xyz="2.77555756156289E-17 0.00301625201723221 -1.38777878078145E-17"/>
      <mass value="0.000973255657328892"/>
      <inertia ixx="6.26992620308679E-07" ixy="3.59808441353406E-24" ixz="7.98941079078556E-09" iyy="6.38900379274268E-07" iyz="7.60544173089602E-24" izz="1.55888758686964E-08"/>
    </inertial>
    <visual>
      <origin rpy="0 0 0" xyz="0 0 0"/>
      <geometry>
        <mesh filename="package://drone/meshes/prop_3.STL"/>
      </geometry>
      <material name="">
        <color rgba="0.286274509803922 0.662745098039216 0.329411764705882 1"/>
      </material>
    </visual>
    <collision>
      <origin rpy="0 0 0" xyz="0 0 0"/>
      <geometry>
        <mesh filename="package://drone/meshes/prop_3.STL"/>
      </geometry>
    </collision>
  </link>
  <joint name="motor_3" type="continuous">
    <origin rpy="1.5708 0 -1.5516" xyz="0.084853 -0.084853 0.0305"/>
    <parent link="base_link"/>
    <child link="prop_3"/>
    <axis xyz="0 1 0"/>
    <limit effort="1000000" lower="-1000000" upper="1000000" velocity="1000000"/>
  </joint>
  <link name="prop_4">
    <inertial>
      <origin rpy="0 0 0" xyz="2.77555756156289E-17 0.00301625201723221 0"/>
      <mass value="0.000973255657328888"/>
      <inertia ixx="6.26992620308678E-07" ixy="7.16859571560985E-24" ixz="7.98941079078488E-09" iyy="6.38900379274267E-07" iyz="2.55140400374983E-23" izz="1.55888758686963E-08"/>
    </inertial>
    <visual>
      <origin rpy="0 0 0" xyz="0 0 0"/>
      <geometry>
        <mesh filename="package://drone/meshes/prop_4.STL"/>
      </geometry>
      <material name="">
        <color rgba="0.286274509803922 0.662745098039216 0.329411764705882 1"/>
      </material>
    </visual>
    <collision>
      <origin rpy="0 0 0" xyz="0 0 0"/>
      <geometry>
        <mesh filename="package://drone/meshes/prop_4.STL"/>
      </geometry>
    </collision>
  </link>
  <joint name="motor_4" type="continuous">
    <origin rpy="1.5708 0 0.039629" xyz="-0.084853 -0.084853 0.0305"/>
    <parent link="base_link"/>
    <child link="prop_4"/>
    <axis xyz="0 1 0"/>
    <limit effort="1000000" lower="-1000000" upper="1000000" velocity="1000000"/>
  </joint>
  <link name="imu_link">
    <inertial>
      <mass value="0.001"/>
      <origin rpy="0 0 0" xyz="0 0 0"/>
      <inertia ixx="0.0001" ixy="0" ixz="0" iyy="0.000001" iyz="0" izz="0.0001"/>
    </inertial>
    <visual>
      <origin rpy="0 0 0" xyz="0 0 0"/>
      <geometry>
        <box size="0.01 0.01 0.01"/>
      </geometry>
      <material name="red"/>
    </visual>
    <collision>
      <origin rpy="0 0 0" xyz="0 0 0"/>
      <geometry>
        <box size=".01 .01 .01"/>
      </geometry>
    </collision>
  </link>
  <joint name="imu_joint" type="fixed">
    <axis xyz="1 0 0"/>
    <origin xyz="0 0 0.05"/>
    <parent link="base_link"/>
    <child link="imu_link"/>
  </joint>
  <gazebo reference="prop_1">
    <material>Gazebo/Green</material>
  </gazebo>
  <gazebo reference="prop_2">
    <material>Gazebo/Green</material>
  </gazebo>
  <gazebo reference="prop_3">
    <material>Gazebo/Green</material>
  </gazebo>
  <gazebo reference="prop_4">
    <material>Gazebo/Green</material>
  </gazebo>
  <gazebo reference="imu_link">
    <material>Gazebo/Orange</material>
  </gazebo>
  <!-- Transmission -->
  <transmission name="trans_motor1">
    <type>transmission_interface/SimpleTransmission</type>
    <joint name="motor_1">
      <hardwareInterface>hardware_interface/VelocityJointInterface</hardwareInterface>
    </joint>
    <actuator name="motor1">
      <hardwareInterface>hardware_interface/VelocityJointInterface</hardwareInterface>
      <mechanicalReduction>1</mechanicalReduction>
    </actuator>
  </transmission>
  <transmission name="trans_motor2">
    <type>transmission_interface/SimpleTransmission</type>
    <joint name="motor_2">
      <hardwareInterface>hardware_interface/VelocityJointInterface</hardwareInterface>
    </joint>
    <actuator name="motor2">
      <hardwareInterface>hardware_interface/VelocityJointInterface</hardwareInterface>
      <mechanicalReduction>1</mechanicalReduction>
    </actuator>
  </transmission>
  <transmission name="trans_motor3">
    <type>transmission_interface/SimpleTransmission</type>
    <joint name="motor_3">
      <hardwareInterface>hardware_interface/VelocityJointInterface</hardwareInterface>
    </joint>
    <actuator name="motor3">
      <hardwareInterface>hardware_interface/VelocityJointInterface</hardwareInterface>
      <mechanicalReduction>1</mechanicalReduction>
    </actuator>
  </transmission>
  <transmission name="trans_motor4">
    <type>transmission_interface/SimpleTransmission</type>
    <joint name="motor_4">
      <hardwareInterface>hardware_interface/VelocityJointInterface</hardwareInterface>
    </joint>
    <actuator name="motor4">
      <hardwareInterface>hardware_interface/VelocityJointInterface</hardwareInterface>
      <mechanicalReduction>1</mechanicalReduction>
    </actuator>
  </transmission>
  <gazebo>
    <plugin filename="libgazebo_ros_control.so" name="gazebo_ros_control">
      <robotNamespace>/drone</robotNamespace>
      <robotSimType>gazebo_ros_control/DefaultRobotHWSim</robotSimType>
      <legacyModeNS>true</legacyModeNS>
    </plugin>
    <plugin filename="libdrone_plugin.so" name="drone_plugin">
      <updateRate>500</updateRate>
      <publishTf>true</publishTf>
      <rotorThrustCoeff>0.00001</rotorThrustCoeff>
      <rotorTorqueCoeff>0.0000004</rotorTorqueCoeff>
    </plugin>
    <plugin filename="libgazebo_ros_imu.so" name="imu_plugin">
      <alwaysOn>true</alwaysOn>
      <bodyName>imu_link</bodyName>
      <topicName>drone/imu</topicName>
      <frameName>imu_link</frameName>
      <serviceName>imu_service</serviceName>
      <gaussianNoise>0.0</gaussianNoise>
      <updateRate>20.0</updateRate>
    </plugin>
  </gazebo>
</robot>
